#VRML_SIM R2023b utf8

WorldInfo {
  CFM 1e-07
  ERP 0.8
  basicTimeStep 2
  contactProperties [
    ContactProperties {
      material1 "robot_material"
      material2 "robot_material"
      coulombFriction [
        0.7
      ]
      bounce 0.8
      bounceVelocity 0.003
      softERP 0.42
      softCFM 0.000208
    }
    ContactProperties {
      material1 "f"
      material2 "r"
      coulombFriction [
        0.7
      ]
      bounce 0.8
      bounceVelocity 0.003
      softERP 0.42
      softCFM 0.000208
    }
  ]
}
Viewpoint {
  orientation -0.018745956911824433 -0.017722049634692354 0.9996672036513978 4.655917675739395
  position 0.015267072622161315 2.3944163385515904 1.12224569236043
}
# Due to url rewrite of webots-server, the relative path of the images is changed.
# And need to add a referece to the images from here for the resource loading in webots.
Background {
  skyColor [
    0.3 0.5 0.9
  ]
  backUrl [
    "./background/129072673_back.jpg"
  ]
  bottomUrl [
    "./background/129072673_bottom.jpg"
  ]
  frontUrl [
    "./background/129072673_front.jpg"
  ]
  leftUrl [
    "./background/129072673_left.jpg"
  ]
  rightUrl [
    "./background/129072673_right.jpg"
  ]
  topUrl [
    "./background/129072673_top.jpg"
  ]
}
DirectionalLight {
  direction -1 0 -1
  intensity 3
}
Solid {
  boundingObject Shape {
    appearance PBRAppearance {
    }
    geometry Plane {
      size 10 10
    }
  }
}
DEF Sonny Robot {
  translation 0 -1.06 0.952
  rotation 0 0 1 -1.5707953071795862
  children [
    Shape {
      appearance DEF base_material PBRAppearance {
        baseColor 0.15 0.15 0.15
        roughness 1
        metalness 0
      }
      geometry DEF base Mesh {
        url [
          "../meshes/base.STL"
        ]
      }
      castShadows FALSE
    }
    Pose {
      translation -0.065 0 -0.084
      rotation 1 0 0 0
      children [
        InertialUnit {
          name "inertial_unit"
        }
        Gyro {
        }
        Accelerometer {
        }
        Shape {
          appearance PBRAppearance {
            baseColor 0.643137 0 0
          }
          geometry Box {
            size 0.02 0.015 0.006
          }
        }
      ]
    }
    HingeJoint {
      jointParameters HingeJointParameters {
        axis 1 0 1.2e-05
        anchor -0.047999 0.105 -0.057493
      }
      device [
        RotationalMotor {
          name "LLeg1"
          maxVelocity 12.15
          minPosition -0.09
          maxPosition 0.79
          maxTorque 100
        }
        PositionSensor {
          name "LLeg1_sensor"
        }
      ]
      endPoint Solid {
        translation -0.047999 0.105 -0.057493
        rotation 0.999999999928 0 1.1999999999136001e-05 0
        children [
          Shape {
            appearance DEF LLeg1_material PBRAppearance {
              baseColor 0.15 0.15 0.15
              roughness 1
              metalness 0
            }
            geometry DEF LLeg1 Mesh {
              url [
                "../meshes/LLeg1.STL"
              ]
            }
          }
          HingeJoint {
            jointParameters HingeJointParameters {
              axis 1.2e-05 6.8e-05 1
              anchor 0.048 0 -0.030499
            }
            device [
              RotationalMotor {
                name "LLeg2"
                maxVelocity 16.76
                minPosition -0.7
                maxPosition 0.7
                maxTorque 100
              }
              PositionSensor {
                name "LLeg2_sensor"
              }
            ]
            endPoint Solid {
              translation 0.048 0 -0.030499
              rotation 1.1999999971392001e-05 6.7999999837888e-05 0.9999999976160001 0
              children [
                Shape {
                  appearance DEF LLeg2_material PBRAppearance {
                    baseColor 0.15 0.15 0.15
                    roughness 1
                    metalness 0
                  }
                  geometry DEF LLeg2 Mesh {
                    url [
                      "../meshes/LLeg2.STL"
                    ]
                  }
                }
                HingeJoint {
                  jointParameters HingeJointParameters {
                    axis 0 1 -6.8e-05
                    anchor 0 0 -0.11
                  }
                  device [
                    RotationalMotor {
                      name "LLeg3"
                      maxVelocity 37.38
                      minPosition -1.75
                      maxPosition 0.7
                      maxTorque 250
                    }
                    PositionSensor {
                      name "LLeg3_sensor"
                    }
                  ]
                  endPoint Solid {
                    translation 0 0 -0.11
                    rotation 0 0.9999999976880001 -6.7999999842784e-05 0
                    children [
                      Shape {
                        appearance DEF LLeg3_material PBRAppearance {
                          baseColor 0.15 0.15 0.15
                          roughness 1
                          metalness 0
                        }
                        geometry DEF LLeg3 Mesh {
                          url [
                            "../meshes/LLeg3.STL"
                          ]
                        }
                        castShadows FALSE
                      }
                      HingeJoint {
                        jointParameters HingeJointParameters {
                          axis 0 1 6.8e-05
                          anchor 0 2.5e-05 -0.36
                        }
                        device [
                          RotationalMotor {
                            name "LLeg4"
                            maxVelocity 37.38
                            minPosition -0.09
                            maxPosition 1.92
                            maxTorque 225
                          }
                          PositionSensor {
                            name "LLeg4_sensor"
                          }
                        ]
                        endPoint Solid {
                          translation 0 2.5e-05 -0.36
                          rotation 0 0.9999999976880001 6.7999999842784e-05 0
                          children [
                            Shape {
                              appearance DEF LLeg4_material PBRAppearance {
                                baseColor 0.15 0.15 0.15
                                roughness 1
                                metalness 0
                              }
                              geometry DEF LLeg4 Mesh {
                                url [
                                  "../meshes/LLeg4.STL"
                                ]
                              }
                              castShadows FALSE
                            }
                            HingeJoint {
                              jointParameters HingeJointParameters {
                                axis 0 1 6.8e-05
                                anchor 0 2.3e-05 -0.34
                              }
                              device [
                                RotationalMotor {
                                  name "LLeg5"
                                  maxVelocity 20.32
                                  minPosition -1.05
                                  maxPosition 0.52
                                  maxTorque 64
                                }
                                PositionSensor {
                                  name "LLeg5_sensor"
                                }
                              ]
                              endPoint Solid {
                                translation 0 2.3e-05 -0.34
                                rotation 0 0.9999999976880001 6.7999999842784e-05 0
                                children [
                                  Shape {
                                    appearance DEF LLeg5_material PBRAppearance {
                                      baseColor 0.15 0.15 0.15
                                      roughness 1
                                      metalness 0
                                    }
                                    geometry DEF LLeg5 Mesh {
                                      url [
                                        "../meshes/LLeg5.STL"
                                      ]
                                    }
                                  }
                                  HingeJoint {
                                    jointParameters HingeJointParameters {
                                      axis 1 0 1.2e-05
                                    }
                                    device [
                                      RotationalMotor {
                                        name "LLeg6"
                                        maxVelocity 20.32
                                        minPosition -0.44
                                        maxPosition 0.44
                                        maxTorque 32
                                      }
                                      PositionSensor {
                                        name "LLeg6_sensor"
                                      }
                                    ]
                                    endPoint Solid {
                                      rotation 0.999999999928 0 1.1999999999136001e-05 0
                                      children [
                                        Shape {
                                          appearance DEF LLeg6_material PBRAppearance {
                                            baseColor 0.15 0.15 0.15
                                            roughness 1
                                            metalness 0
                                          }
                                          geometry DEF LLeg6 Mesh {
                                            url [
                                              "../meshes/LLeg6.STL"
                                            ]
                                          }
                                          castShadows FALSE
                                        }
                                      ]
                                      name "LLeg6"
                                      boundingObject Group {
                                        children [
                                          Pose {
                                            translation 0.05 0.02 -0.035
                                            rotation 0 1 0 1.5708
                                            children [
                                              Cylinder {
                                                height 0.24
                                                radius 0.02
                                              }
                                            ]
                                          }
                                          Pose {
                                            translation 0.05 -0.02 -0.035
                                            rotation 0 1 0 1.5708
                                            children [
                                              Cylinder {
                                                height 0.24
                                                radius 0.02
                                              }
                                            ]
                                          }
                                        ]
                                      }
                                      physics Physics {
                                        density -1
                                        mass 0.584
                                        centerOfMass [
                                          0.039446 0.000358 -0.038101
                                        ]
                                        inertiaMatrix [
                                          0.00036926 0.0024027 0.0027102
                                          2.5654e-06 1.6145e-05 -1.171e-06
                                        ]
                                      }
                                    }
                                  }
                                ]
                                name "LLeg5"
                                physics Physics {
                                  density -1
                                  mass 0.080335
                                  centerOfMass [
                                    0 0 0
                                  ]
                                  inertiaMatrix [
                                    5.1022e-06 4.3976e-06 4.188e-06
                                    -7.7589e-16 1.1105e-11 1.4349e-11
                                  ]
                                }
                              }
                            }
                          ]
                          name "LLeg4"
                          boundingObject Pose {
                            translation 0 0 -0.15
                            children [
                              Cylinder {
                                height 0.2
                                radius 0.05
                              }
                            ]
                          }
                          physics Physics {
                            density -1
                            mass 2.1895
                            centerOfMass [
                              0.002431 -3e-05 -0.11554
                            ]
                            inertiaMatrix [
                              0.016117 0.01627 0.0011365
                              -6.426e-06 -5.8179e-05 -2.4143e-06
                            ]
                          }
                        }
                      }
                    ]
                    name "LLeg3"
                    boundingObject Pose {
                      translation 0 0 -0.15
                      children [
                        Cylinder {
                          height 0.35
                          radius 0.05
                        }
                      ]
                    }
                    physics Physics {
                      density -1
                      mass 6.369
                      centerOfMass [
                        0.002849 -0.021688 -0.090886
                      ]
                      inertiaMatrix [
                        0.042477 0.053235 0.013469
                        1.4561e-05 0.00097249 -8.0062e-05
                      ]
                    }
                  }
                }
              ]
              name "LLeg2"
              physics Physics {
                density -1
                mass 3.9888
                centerOfMass [
                  0.000183 0.046462 -0.10389
                ]
                inertiaMatrix [
                  0.010009 0.016331 0.0092577
                  -4.6866e-05 7.2342e-05 0.00022608
                ]
              }
            }
          }
        ]
        name "LLeg1"
        physics Physics {
          density -1
          mass 1.1437
          centerOfMass [
            0.04163 3.5e-05 -0.002138
          ]
          inertiaMatrix [
            0.0010239 0.0009439 0.0011557
            9.9505e-08 5.4748e-05 -1.1272e-06
          ]
        }
      }
    }
    HingeJoint {
      jointParameters HingeJointParameters {
        axis 1 0 1.2e-05
        anchor -0.047999 -0.105 -0.057508
      }
      device [
        RotationalMotor {
          name "RLeg1"
          maxVelocity 12.15
          minPosition -0.79
          maxPosition 0.09
          maxTorque 100
        }
        PositionSensor {
          name "RLeg1_sensor"
        }
      ]
      endPoint Solid {
        translation -0.047999 -0.105 -0.057508
        rotation 0.999999999928 0 1.1999999999136001e-05 0
        children [
          Shape {
            appearance DEF RLeg1_material PBRAppearance {
              baseColor 0.15 0.15 0.15
              roughness 1
              metalness 0
            }
            geometry DEF RLeg1 Mesh {
              url [
                "../meshes/RLeg1.STL"
              ]
            }
          }
          HingeJoint {
            jointParameters HingeJointParameters {
              axis 1.2e-05 6.8e-05 1
              anchor 0.048 0 -0.030499
            }
            device [
              RotationalMotor {
                name "RLeg2"
                maxVelocity 16.76
                minPosition -0.7
                maxPosition 0.7
                maxTorque 100
              }
              PositionSensor {
                name "RLeg2_sensor"
              }
            ]
            endPoint Solid {
              translation 0.048 0 -0.030499
              rotation 1.1999999971392001e-05 6.7999999837888e-05 0.9999999976160001 0
              children [
                Shape {
                  appearance DEF RLeg2_material PBRAppearance {
                    baseColor 0.15 0.15 0.15
                    roughness 1
                    metalness 0
                  }
                  geometry DEF RLeg2 Mesh {
                    url [
                      "../meshes/RLeg2.STL"
                    ]
                  }
                }
                HingeJoint {
                  jointParameters HingeJointParameters {
                    axis 0 1 6.8e-05
                    anchor 0 0 -0.11
                  }
                  device [
                    RotationalMotor {
                      name "RLeg3"
                      maxVelocity 37.38
                      minPosition -1.75
                      maxPosition 0.7
                      maxTorque 225
                    }
                    PositionSensor {
                      name "RLeg3_sensor"
                    }
                  ]
                  endPoint Solid {
                    translation 0 0 -0.11
                    rotation 0 0.9999999976880001 6.7999999842784e-05 0
                    children [
                      Shape {
                        appearance DEF RLeg3_material PBRAppearance {
                          baseColor 0.15 0.15 0.15
                          roughness 1
                          metalness 0
                        }
                        geometry DEF RLeg3 Mesh {
                          url [
                            "../meshes/RLeg3.STL"
                          ]
                        }
                        castShadows FALSE
                      }
                      HingeJoint {
                        jointParameters HingeJointParameters {
                          axis 0 1 -6.8e-05
                          anchor 0 2.5e-05 -0.36
                        }
                        device [
                          RotationalMotor {
                            name "RLeg4"
                            maxVelocity 37.38
                            minPosition -0.09
                            maxPosition 1.92
                            maxTorque 250
                          }
                          PositionSensor {
                            name "RLeg4_sensor"
                          }
                        ]
                        endPoint Solid {
                          translation 0 2.5e-05 -0.36
                          rotation 0 0.9999999976880001 -6.7999999842784e-05 0
                          children [
                            Shape {
                              appearance DEF RLeg4_material PBRAppearance {
                                baseColor 0.15 0.15 0.15
                                roughness 1
                                metalness 0
                              }
                              geometry DEF RLeg4 Mesh {
                                url [
                                  "../meshes/RLeg4.STL"
                                ]
                              }
                              castShadows FALSE
                            }
                            HingeJoint {
                              jointParameters HingeJointParameters {
                                axis 0 1 6.8e-05
                                anchor 0 2.3e-05 -0.34
                              }
                              device [
                                RotationalMotor {
                                  name "RLeg5"
                                  maxVelocity 20.32
                                  minPosition -1.05
                                  maxPosition 0.52
                                  maxTorque 64
                                }
                                PositionSensor {
                                  name "RLeg5_sensor"
                                }
                              ]
                              endPoint Solid {
                                translation 0 2.3e-05 -0.34
                                rotation 0 0.9999999976880001 6.7999999842784e-05 0
                                children [
                                  Shape {
                                    appearance DEF RLeg5_material PBRAppearance {
                                      baseColor 0.15 0.15 0.15
                                      roughness 1
                                      metalness 0
                                    }
                                    geometry DEF RLeg5 Mesh {
                                      url [
                                        "../meshes/RLeg5.STL"
                                      ]
                                    }
                                  }
                                  HingeJoint {
                                    jointParameters HingeJointParameters {
                                      axis 1 0 1.2e-05
                                    }
                                    device [
                                      RotationalMotor {
                                        name "RLeg6"
                                        maxVelocity 20.32
                                        minPosition -0.44
                                        maxPosition 0.44
                                        maxTorque 32
                                      }
                                      PositionSensor {
                                        name "RLeg6_sensor"
                                      }
                                    ]
                                    endPoint Solid {
                                      rotation 0.999999999928 0 1.1999999999136001e-05 0
                                      children [
                                        Shape {
                                          appearance DEF RLeg6_material PBRAppearance {
                                            baseColor 0.15 0.15 0.15
                                            roughness 1
                                            metalness 0
                                          }
                                          geometry DEF RLeg6 Mesh {
                                            url [
                                              "../meshes/RLeg6.STL"
                                            ]
                                          }
                                          castShadows FALSE
                                        }
                                      ]
                                      name "RLeg6"
                                      boundingObject Group {
                                        children [
                                          Pose {
                                            translation 0.05 0.02 -0.035
                                            rotation 0 1 0 1.5708
                                            children [
                                              Cylinder {
                                                height 0.24
                                                radius 0.02
                                              }
                                            ]
                                          }
                                          Pose {
                                            translation 0.05 -0.02 -0.035
                                            rotation 0 1 0 1.5708
                                            children [
                                              Cylinder {
                                                height 0.24
                                                radius 0.02
                                              }
                                            ]
                                          }
                                        ]
                                      }
                                      physics Physics {
                                        density -1
                                        mass 0.58089
                                        centerOfMass [
                                          0.043909 -0.000325 -0.039419
                                        ]
                                        inertiaMatrix [
                                          0.00036866 0.0024886 0.0028008
                                          -2.4583e-06 2.061e-05 1.0326e-06
                                        ]
                                      }
                                    }
                                  }
                                ]
                                name "RLeg5"
                                physics Physics {
                                  density -1
                                  mass 0.079922
                                  centerOfMass [
                                    0 0 0
                                  ]
                                  inertiaMatrix [
                                    5.111224e-06 4.400038e-06 4.179536e-06
                                    -7.904633e-16 1.131832e-11 1.509717e-11
                                  ]
                                }
                              }
                            }
                          ]
                          name "RLeg4"
                          boundingObject Pose {
                            translation 0 0 -0.15
                            children [
                              Cylinder {
                                height 0.2
                                radius 0.05
                              }
                            ]
                          }
                          physics Physics {
                            density -1
                            mass 2.189466
                            centerOfMass [
                              0.002367 4.6e-05 -0.115532
                            ]
                            inertiaMatrix [
                              0.01611819 0.01627058 0.001135585
                              5.079991e-06 -5.800472e-05 8.200546e-06
                            ]
                          }
                        }
                      }
                    ]
                    name "RLeg3"
                    boundingObject Pose {
                      translation 0 0 -0.15
                      children [
                        Cylinder {
                          height 0.35
                          radius 0.05
                        }
                      ]
                    }
                    physics Physics {
                      density -1
                      mass 6.368953
                      centerOfMass [
                        0.002842 0.021701 -0.091999
                      ]
                      inertiaMatrix [
                        0.04244834 0.05323475 0.01349767
                        -1.479276e-05 0.0009842815 7.054312e-05
                      ]
                    }
                  }
                }
              ]
              name "RLeg2"
              physics Physics {
                density -1
                mass 3.988819
                centerOfMass [
                  -0.001598 -0.046448 -0.103899
                ]
                inertiaMatrix [
                  0.01000893 0.0163311 0.009257637
                  6.177076e-05 6.455771e-05 -0.0002251136
                ]
              }
            }
          }
        ]
        name "RLeg1"
        physics Physics {
          density -1
          mass 1.143665
          centerOfMass [
            0.04163 3.5e-05 -0.002138
          ]
          inertiaMatrix [
            0.001023949 0.0009438991 0.001155695
            9.950853e-08 5.474751e-05 -1.127247e-06
          ]
        }
      }
    }
    HingeJoint {
      jointParameters HingeJointParameters {
        axis -1.2e-05 -6.8e-05 1
        anchor 0 0 0.0065
      }
      device [
        RotationalMotor {
          name "waist_yaw"
          maxVelocity 16.76
          minPosition -1.05
          maxPosition 1.05
          maxTorque 200
        }
        PositionSensor {
          name "waist_yaw_sensor"
        }
      ]
      endPoint Solid {
        translation 0 0 0.0065
        rotation -1.1999999971392001e-05 -6.7999999837888e-05 0.9999999976160001 0
        children [
          Shape {
            appearance DEF waist_yaw_material PBRAppearance {
              baseColor 0.15 0.15 0.15
              roughness 1
              metalness 0
            }
            geometry DEF waist_yaw Mesh {
              url [
                "../meshes/waist_yaw.STL"
              ]
            }
          }
          HingeJoint {
            jointParameters HingeJointParameters {
              axis 0 1 -6.8e-05
              anchor 0 0 0.055
            }
            device [
              RotationalMotor {
                name "waist_pitch"
                maxVelocity 16.76
                minPosition -0.52
                maxPosition 1.22
                maxTorque 200
              }
              PositionSensor {
                name "waist_pitch_sensor"
              }
            ]
            endPoint Solid {
              translation 0 0 0.055
              rotation 0 0.9999999976880001 -6.7999999842784e-05 0
              children [
                Shape {
                  appearance DEF waist_pitch_material PBRAppearance {
                    baseColor 0.15 0.15 0.15
                    roughness 1
                    metalness 0
                  }
                  geometry DEF waist_pitch Mesh {
                    url [
                      "../meshes/waist_pitch.STL"
                    ]
                  }
                }
                HingeJoint {
                  jointParameters HingeJointParameters {
                    axis 1 0 1.2e-05
                    anchor 0 0 0.085
                  }
                  device [
                    RotationalMotor {
                      name "waist_roll"
                      maxVelocity 16.76
                      minPosition -0.7
                      maxPosition 0.7
                      maxTorque 200
                    }
                    PositionSensor {
                      name "waist_roll_sensor"
                    }
                  ]
                  endPoint Solid {
                    translation 0 0 0.085
                    rotation 0.999999999928 0 1.1999999999136001e-05 0
                    children [
                      Shape {
                        appearance DEF waist_roll_material PBRAppearance {
                          baseColor 0.15 0.15 0.15
                          roughness 1
                          metalness 0
                        }
                        geometry DEF waist_roll Mesh {
                          url [
                            "../meshes/waist_roll.STL"
                          ]
                        }
                      }
                      HingeJoint {
                        jointParameters HingeJointParameters {
                          axis 0 0.906279 0.42268
                          anchor 0 0.12661 0.21727
                        }
                        device [
                          RotationalMotor {
                            name "LArm1"
                            maxVelocity 9.11
                            minPosition -2.79
                            maxPosition 1.92
                            maxTorque 38
                          }
                          PositionSensor {
                            name "LArm1_sensor"
                          }
                        ]
                        endPoint Solid {
                          translation 0 0.12661 0.21727
                          rotation 0.9999999999999999 0 0 0.4363999999999997
                          children [
                            Shape {
                              appearance DEF LArm1_material PBRAppearance {
                                baseColor 0.15 0.15 0.15
                                roughness 1
                                metalness 0
                              }
                              geometry DEF LArm1 Mesh {
                                url [
                                  "../meshes/LArm1.STL"
                                ]
                              }
                              castShadows FALSE
                            }
                            HingeJoint {
                              jointParameters HingeJointParameters {
                                axis 1 -5e-06 -1.1e-05
                                anchor 0 0.067 0
                              }
                              device [
                                RotationalMotor {
                                  name "LArm2"
                                  maxVelocity 9.11
                                  minPosition -0.57
                                  maxPosition 3.27
                                  maxTorque 38
                                }
                                PositionSensor {
                                  name "LArm2_sensor"
                                }
                              ]
                              endPoint Solid {
                                translation 0 0.067 0
                                rotation -0.9999999999999999 0 0 0.4363999999999997
                                children [
                                  Shape {
                                    appearance DEF LArm2_material PBRAppearance {
                                      baseColor 0.15 0.15 0.15
                                      roughness 1
                                      metalness 0
                                    }
                                    geometry DEF LArm2 Mesh {
                                      url [
                                        "../meshes/LArm2.STL"
                                      ]
                                    }
                                  }
                                  HingeJoint {
                                    jointParameters HingeJointParameters {
                                      axis 1.2e-05 6.8e-05 1
                                      anchor 0 0.040004 -0.057502
                                    }
                                    device [
                                      RotationalMotor {
                                        name "LArm3"
                                        maxVelocity 7.33
                                        minPosition -2.97
                                        maxPosition 2.97
                                        maxTorque 30
                                      }
                                      PositionSensor {
                                        name "LArm3_sensor"
                                      }
                                    ]
                                    endPoint Solid {
                                      translation 0 0.040004 -0.057502
                                      rotation 1.1999999971392001e-05 6.7999999837888e-05 0.9999999976160001 0
                                      children [
                                        Shape {
                                          appearance DEF LArm3_material PBRAppearance {
                                            baseColor 0.15 0.15 0.15
                                            roughness 1
                                            metalness 0
                                          }
                                          geometry DEF LArm3 Mesh {
                                            url [
                                              "../meshes/LArm3.STL"
                                            ]
                                          }
                                          castShadows FALSE
                                        }
                                        HingeJoint {
                                          jointParameters HingeJointParameters {
                                            axis 0 1 6.8e-05
                                            anchor 0 1.3e-05 -0.188546
                                          }
                                          device [
                                            RotationalMotor {
                                              name "LArm4"
                                              maxVelocity 7.33
                                              minPosition -2.27
                                              maxPosition 2.27
                                              maxTorque 30
                                            }
                                            PositionSensor {
                                              name "LArm4_sensor"
                                            }
                                          ]
                                          endPoint Solid {
                                            translation 0 1.3e-05 -0.188546
                                            rotation 0 0.9999999976880001 6.7999999842784e-05 0
                                            children [
                                              Shape {
                                                appearance DEF LArm4_material PBRAppearance {
                                                  baseColor 0.15 0.15 0.15
                                                  roughness 1
                                                  metalness 0
                                                }
                                                geometry DEF LArm4 Mesh {
                                                  url [
                                                    "../meshes/LArm4.STL"
                                                  ]
                                                }
                                              }
                                              HingeJoint {
                                                jointParameters HingeJointParameters {
                                                  axis 1.2e-05 6.8e-05 1
                                                  anchor 0 0 -0.040504
                                                }
                                                device [
                                                  RotationalMotor {
                                                    name "LArm5"
                                                    maxVelocity 24.4
                                                    minPosition -2.97
                                                    maxPosition 2.97
                                                    maxTorque 10.2
                                                  }
                                                  PositionSensor {
                                                    name "LArm5_sensor"
                                                  }
                                                ]
                                                endPoint Solid {
                                                  translation 0 0 -0.040504
                                                  rotation 1.1999999971392001e-05 6.7999999837888e-05 0.9999999976160001 0
                                                  children [
                                                    Shape {
                                                      appearance DEF LArm5_material PBRAppearance {
                                                        baseColor 0.15 0.15 0.15
                                                        roughness 1
                                                        metalness 0
                                                      }
                                                      geometry DEF LArm5 Mesh {
                                                        url [
                                                          "../meshes/LArm5.STL"
                                                        ]
                                                      }
                                                      castShadows FALSE
                                                    }
                                                    HingeJoint {
                                                      jointParameters HingeJointParameters {
                                                        axis 1 0 -1.2e-05
                                                        anchor 0 1.4e-05 -0.20155
                                                      }
                                                      device [
                                                        RotationalMotor {
                                                          name "LArm6"
                                                          maxVelocity 27.96
                                                          minPosition -0.96
                                                          maxPosition 0.87
                                                          maxTorque 3.95
                                                        }
                                                        PositionSensor {
                                                          name "LArm6_sensor"
                                                        }
                                                      ]
                                                      endPoint Solid {
                                                        translation 0 1.4e-05 -0.20155
                                                        rotation 0.999999999928 0 -1.1999999999136001e-05 0
                                                        children [
                                                          Shape {
                                                            appearance DEF LArm6_material PBRAppearance {
                                                              baseColor 0.15 0.15 0.15
                                                              roughness 1
                                                              metalness 0
                                                            }
                                                            geometry DEF LArm6 Mesh {
                                                              url [
                                                                "../meshes/LArm6.STL"
                                                              ]
                                                            }
                                                          }
                                                          HingeJoint {
                                                            jointParameters HingeJointParameters {
                                                              axis 0 1 6.8e-05
                                                            }
                                                            device [
                                                              RotationalMotor {
                                                                name "LArm7"
                                                                maxVelocity 27.96
                                                                minPosition -0.61
                                                                maxPosition 0.61
                                                                maxTorque 3.95
                                                              }
                                                              PositionSensor {
                                                                name "LArm7_sensor"
                                                              }
                                                            ]
                                                            endPoint Solid {
                                                              rotation 0 0.9999999976880001 6.7999999842784e-05 0
                                                              children [
                                                                Shape {
                                                                  appearance DEF LArm7_material PBRAppearance {
                                                                    baseColor 0.15 0.15 0.15
                                                                    roughness 1
                                                                    metalness 0
                                                                  }
                                                                  geometry DEF LArm7 Mesh {
                                                                    url [
                                                                      "../meshes/LArm7.STL"
                                                                    ]
                                                                  }
                                                                  castShadows FALSE
                                                                }
                                                              ]
                                                              name "LArm7"
                                                              boundingObject Pose {
                                                                translation 0 0 -0.07
                                                                children [
                                                                  Sphere {
                                                                    radius 0.05
                                                                  }
                                                                ]
                                                              }
                                                              physics Physics {
                                                                density -1
                                                                mass 0.5239
                                                                centerOfMass [
                                                                  0.007129 -0.002619 -0.078567
                                                                ]
                                                                inertiaMatrix [
                                                                  0.00020226 0.00034574 0.00020545
                                                                  1.8145e-06 7.7506e-06 2.8432e-06
                                                                ]
                                                              }
                                                            }
                                                          }
                                                        ]
                                                        name "LArm6"
                                                        physics Physics {
                                                          density -1
                                                          mass 0.005447
                                                          centerOfMass [
                                                            0 -0.000448 0
                                                          ]
                                                          inertiaMatrix [
                                                            7.344e-08 3.5527e-07 3.6036e-07
                                                            -5.3228e-13 -5.6785e-12 -1.577e-13
                                                          ]
                                                        }
                                                      }
                                                    }
                                                  ]
                                                  name "LArm5"
                                                  boundingObject Pose {
                                                    translation 0 0 -0.08
                                                    children [
                                                      Cylinder {
                                                        height 0.17
                                                        radius 0.035
                                                      }
                                                    ]
                                                  }
                                                  physics Physics {
                                                    density -1
                                                    mass 0.606076
                                                    centerOfMass [
                                                      -4.2e-05 0.000336 -0.055983
                                                    ]
                                                    inertiaMatrix [
                                                      0.0007471748 0.0007086471 0.0002814709
                                                      6.196846e-07 6.378258e-06 -1.620663e-05
                                                    ]
                                                  }
                                                }
                                              }
                                            ]
                                            name "LArm4"
                                            physics Physics {
                                              density -1
                                              mass 0.055396
                                              centerOfMass [
                                                0 0.019694 -0.02109
                                              ]
                                              inertiaMatrix [
                                                2.63267e-05 2.410734e-05 1.841127e-05
                                                8.995581e-11 1.022196e-10 -7.439758e-06
                                              ]
                                            }
                                          }
                                        }
                                      ]
                                      name "LArm3"
                                      boundingObject Pose {
                                        translation 0 0 -0.05
                                        children [
                                          Cylinder {
                                            height 0.11
                                            radius 0.03
                                          }
                                        ]
                                      }
                                      physics Physics {
                                        density -1
                                        mass 0.78993
                                        centerOfMass [
                                          -4.1e-05 0.00135 -0.101007
                                        ]
                                        inertiaMatrix [
                                          0.0004203623 0.0004799815 0.0003164909
                                          -4.299352e-08 2.902168e-07 1.203895e-05
                                        ]
                                      }
                                    }
                                  }
                                ]
                                name "LArm2"
                                boundingObject Sphere {
                                  radius 0.04
                                }
                                physics Physics {
                                  density -1
                                  mass 0.084111
                                  centerOfMass [
                                    0.026005 0.02383 -0.027208
                                  ]
                                  inertiaMatrix [
                                    8.865457e-05 6.473849e-05 5.866902e-05
                                    1.102616e-05 -1.683887e-05 2.980325e-05
                                  ]
                                }
                              }
                            }
                          ]
                          name "LArm1"
                          physics Physics {
                            density -1
                            mass 0.777394
                            centerOfMass [
                              0.005157 0.058834 0.000123
                            ]
                            inertiaMatrix [
                              0.0005464095 0.0003405466 0.0003193941
                              4.55001e-07 6.155218e-08 8.623832e-07
                            ]
                          }
                        }
                      }
                      HingeJoint {
                        jointParameters HingeJointParameters {
                          axis 0 0.906334 -0.422562
                          anchor 0 -0.12664 0.21725
                        }
                        device [
                          RotationalMotor {
                            name "RArm1"
                            maxVelocity 9.11
                            minPosition -2.79
                            maxPosition 1.92
                            maxTorque 38
                          }
                          PositionSensor {
                            name "RArm1_sensor"
                          }
                        ]
                        endPoint Solid {
                          translation 0 -0.12664 0.21725
                          rotation -1 0 0 0.43627000000000027
                          children [
                            Shape {
                              appearance DEF RArm1_material PBRAppearance {
                                baseColor 0.15 0.15 0.15
                                roughness 1
                                metalness 0
                              }
                              geometry DEF RArm1 Mesh {
                                url [
                                  "../meshes/RArm1.STL"
                                ]
                              }
                              castShadows FALSE
                            }
                            HingeJoint {
                              jointParameters HingeJointParameters {
                                axis 1 5e-06 -1.1e-05
                                anchor 0 -0.067 0
                              }
                              device [
                                RotationalMotor {
                                  name "RArm2"
                                  maxVelocity 9.11
                                  minPosition -3.27
                                  maxPosition 0.57
                                  maxTorque 38
                                }
                                PositionSensor {
                                  name "RArm2_sensor"
                                }
                              ]
                              endPoint Solid {
                                translation 0 -0.067 0
                                rotation 1 0 0 0.43627000000000027
                                children [
                                  Shape {
                                    appearance DEF RArm2_material PBRAppearance {
                                      baseColor 0.15 0.15 0.15
                                      roughness 1
                                      metalness 0
                                    }
                                    geometry DEF RArm2 Mesh {
                                      url [
                                        "../meshes/RArm2.STL"
                                      ]
                                    }
                                  }
                                  HingeJoint {
                                    jointParameters HingeJointParameters {
                                      axis 1.2e-05 6.8e-05 1
                                      anchor 0 -0.039996 -0.057473
                                    }
                                    device [
                                      RotationalMotor {
                                        name "RArm3"
                                        maxVelocity 7.33
                                        minPosition -2.97
                                        maxPosition 2.97
                                        maxTorque 30
                                      }
                                      PositionSensor {
                                        name "RArm3_sensor"
                                      }
                                    ]
                                    endPoint Solid {
                                      translation 0 -0.039996 -0.057473
                                      rotation 1.1999999971392001e-05 6.7999999837888e-05 0.9999999976160001 0
                                      children [
                                        Shape {
                                          appearance DEF RArm3_material PBRAppearance {
                                            baseColor 0.15 0.15 0.15
                                            roughness 1
                                            metalness 0
                                          }
                                          geometry DEF RArm3 Mesh {
                                            url [
                                              "../meshes/RArm3.STL"
                                            ]
                                          }
                                          castShadows FALSE
                                        }
                                        HingeJoint {
                                          jointParameters HingeJointParameters {
                                            axis 0 1 -6.8e-05
                                            anchor 0 1.3e-05 -0.18853
                                          }
                                          device [
                                            RotationalMotor {
                                              name "RArm4"
                                              maxVelocity 7.33
                                              minPosition -2.27
                                              maxPosition 2.27
                                              maxTorque 30
                                            }
                                            PositionSensor {
                                              name "RArm4_sensor"
                                            }
                                          ]
                                          endPoint Solid {
                                            translation 0 1.3e-05 -0.18853
                                            rotation 0 0.9999999976880001 -6.7999999842784e-05 0
                                            children [
                                              Shape {
                                                appearance DEF RArm4_material PBRAppearance {
                                                  baseColor 0.15 0.15 0.15
                                                  roughness 1
                                                  metalness 0
                                                }
                                                geometry DEF RArm4 Mesh {
                                                  url [
                                                    "../meshes/RArm4.STL"
                                                  ]
                                                }
                                              }
                                              HingeJoint {
                                                jointParameters HingeJointParameters {
                                                  axis 1.2e-05 6.8e-05 1
                                                  anchor 0 0 -0.0405
                                                }
                                                device [
                                                  RotationalMotor {
                                                    name "RArm5"
                                                    maxVelocity 24.4
                                                    minPosition -2.97
                                                    maxPosition 2.97
                                                    maxTorque 10.2
                                                  }
                                                  PositionSensor {
                                                    name "RArm5_sensor"
                                                  }
                                                ]
                                                endPoint Solid {
                                                  translation 0 0 -0.0405
                                                  rotation 1.1999999971392001e-05 6.7999999837888e-05 0.9999999976160001 0
                                                  children [
                                                    Shape {
                                                      appearance DEF RArm5_material PBRAppearance {
                                                        baseColor 0.15 0.15 0.15
                                                        roughness 1
                                                        metalness 0
                                                      }
                                                      geometry DEF RArm5 Mesh {
                                                        url [
                                                          "../meshes/RArm5.STL"
                                                        ]
                                                      }
                                                      castShadows FALSE
                                                    }
                                                    HingeJoint {
                                                      jointParameters HingeJointParameters {
                                                        axis 1 0 1.2e-05
                                                        anchor 0 1.4e-05 -0.20153
                                                      }
                                                      device [
                                                        RotationalMotor {
                                                          name "RArm6"
                                                          maxVelocity 27.96
                                                          minPosition -0.87
                                                          maxPosition 0.96
                                                          maxTorque 3.95
                                                        }
                                                        PositionSensor {
                                                          name "RArm6_sensor"
                                                        }
                                                      ]
                                                      endPoint Solid {
                                                        translation 0 1.4e-05 -0.20153
                                                        rotation 0.999999999928 0 1.1999999999136001e-05 0
                                                        children [
                                                          Shape {
                                                            appearance DEF RArm6_material PBRAppearance {
                                                              baseColor 0.15 0.15 0.15
                                                              roughness 1
                                                              metalness 0
                                                            }
                                                            geometry DEF RArm6 Mesh {
                                                              url [
                                                                "../meshes/RArm6.STL"
                                                              ]
                                                            }
                                                          }
                                                          HingeJoint {
                                                            jointParameters HingeJointParameters {
                                                              axis 0 1 -6.8e-05
                                                            }
                                                            device [
                                                              RotationalMotor {
                                                                name "RArm7"
                                                                maxVelocity 27.96
                                                                minPosition -0.61
                                                                maxPosition 0.61
                                                                maxTorque 3.95
                                                              }
                                                              PositionSensor {
                                                                name "RArm7_sensor"
                                                              }
                                                            ]
                                                            endPoint Solid {
                                                              rotation 0 0.9999999976880001 -6.7999999842784e-05 0
                                                              children [
                                                                Shape {
                                                                  appearance DEF RArm7_material PBRAppearance {
                                                                    baseColor 0.15 0.15 0.15
                                                                    roughness 1
                                                                    metalness 0
                                                                  }
                                                                  geometry DEF RArm7 Mesh {
                                                                    url [
                                                                      "../meshes/RArm7.STL"
                                                                    ]
                                                                  }
                                                                  castShadows FALSE
                                                                }
                                                              ]
                                                              name "RArm7"
                                                              boundingObject Pose {
                                                                translation 0 0 -0.07
                                                                children [
                                                                  Sphere {
                                                                    radius 0.05
                                                                  }
                                                                ]
                                                              }
                                                              physics Physics {
                                                                density -1
                                                                mass 0.53221
                                                                centerOfMass [
                                                                  0.006073 0.001891 -0.084578
                                                                ]
                                                                inertiaMatrix [
                                                                  0.00018966 0.00031983 0.00018923
                                                                  -1.685e-06 6.9527e-06 -3.4284e-06
                                                                ]
                                                              }
                                                            }
                                                          }
                                                        ]
                                                        name "RArm6"
                                                        physics Physics {
                                                          density -1
                                                          mass 0.005447
                                                          centerOfMass [
                                                            0 0.000448 0
                                                          ]
                                                          inertiaMatrix [
                                                            7.344e-08 3.5527e-07 3.6036e-07
                                                            -5.3559e-13 -1.3224e-12 -5.3178e-13
                                                          ]
                                                        }
                                                      }
                                                    }
                                                  ]
                                                  name "RArm5"
                                                  boundingObject Pose {
                                                    translation 0 0 -0.08
                                                    children [
                                                      Cylinder {
                                                        height 0.17
                                                        radius 0.035
                                                      }
                                                    ]
                                                  }
                                                  physics Physics {
                                                    density -1
                                                    mass 0.606076
                                                    centerOfMass [
                                                      0.000158 -0.000479 -0.055942
                                                    ]
                                                    inertiaMatrix [
                                                      0.0007480313 0.0007077895 0.000281472
                                                      -2.385457e-07 -6.674157e-06 1.639051e-05
                                                    ]
                                                  }
                                                }
                                              }
                                            ]
                                            name "RArm4"
                                            physics Physics {
                                              density -1
                                              mass 0.055396
                                              centerOfMass [
                                                0 -0.019691 -0.021093
                                              ]
                                              inertiaMatrix [
                                                2.63267e-05 2.41053e-05 1.84133e-05
                                                -9.173163e-11 9.105033e-11 7.440536e-06
                                              ]
                                            }
                                          }
                                        }
                                      ]
                                      name "RArm3"
                                      boundingObject Pose {
                                        translation 0 0 -0.05
                                        children [
                                          Cylinder {
                                            height 0.11
                                            radius 0.03
                                          }
                                        ]
                                      }
                                      physics Physics {
                                        density -1
                                        mass 0.78993
                                        centerOfMass [
                                          0.000171 -0.001241 -0.100981
                                        ]
                                        inertiaMatrix [
                                          0.0004201623 0.0004802494 0.0003164231
                                          9.567857e-07 -3.819379e-08 -1.181115e-05
                                        ]
                                      }
                                    }
                                  }
                                ]
                                name "RArm2"
                                boundingObject Sphere {
                                  radius 0.04
                                }
                                physics Physics {
                                  density -1
                                  mass 0.084099
                                  centerOfMass [
                                    0.026006 -0.023826 -0.027211
                                  ]
                                  inertiaMatrix [
                                    8.864453e-05 6.4737e-05 5.865264e-05
                                    -1.102183e-05 -1.683685e-05 -2.979911e-05
                                  ]
                                }
                              }
                            }
                          ]
                          name "RArm1"
                          physics Physics {
                            density -1
                            mass 0.777391
                            centerOfMass [
                              0.005157 -0.058792 0.000123
                            ]
                            inertiaMatrix [
                              0.0005464096 0.0003405463 0.000319395
                              -2.018268e-07 6.157571e-08 -1.081677e-06
                            ]
                          }
                        }
                      }
                      HingeJoint {
                        jointParameters HingeJointParameters {
                          axis -1.2e-05 -6.8e-05 1
                          anchor 0 -2.4e-05 0.34453
                        }
                        device [
                          RotationalMotor {
                            name "head_yaw"
                            maxVelocity 24.4
                            minPosition -2.71
                            maxPosition 2.71
                            maxTorque 10.2
                          }
                          PositionSensor {
                            name "head_yaw_sensor"
                          }
                        ]
                        endPoint Solid {
                          translation 0 -2.4e-05 0.34453
                          rotation -1.1999999971392001e-05 -6.7999999837888e-05 0.9999999976160001 0
                          children [
                            Shape {
                              appearance DEF head_yaw_material PBRAppearance {
                                baseColor 0.15 0.15 0.15
                                roughness 1
                                metalness 0
                              }
                              geometry DEF head_yaw Mesh {
                                url [
                                  "../meshes/head_yaw.STL"
                                ]
                              }
                              castShadows FALSE
                            }
                            HingeJoint {
                              jointParameters HingeJointParameters {
                                axis 1 0 1.2e-05
                                anchor 0 0 0.1225
                              }
                              device [
                                RotationalMotor {
                                  name "head_roll"
                                  maxVelocity 27.96
                                  minPosition -0.35
                                  maxPosition 0.35
                                  maxTorque 3.95
                                }
                                PositionSensor {
                                  name "head_roll_sensor"
                                }
                              ]
                              endPoint Solid {
                                translation 0 0 0.1225
                                rotation 0.999999999928 0 1.1999999999136001e-05 0
                                children [
                                  Shape {
                                    appearance DEF head_roll_material PBRAppearance {
                                      baseColor 0.15 0.15 0.15
                                      roughness 1
                                      metalness 0
                                    }
                                    geometry DEF head_roll Mesh {
                                      url [
                                        "../meshes/head_roll.STL"
                                      ]
                                    }
                                  }
                                  HingeJoint {
                                    jointParameters HingeJointParameters {
                                      axis 0 1 6.8e-05
                                    }
                                    device [
                                      RotationalMotor {
                                        name "head_pitch"
                                        maxVelocity 27.96
                                        minPosition -0.52
                                        maxPosition 0.35
                                        maxTorque 3.95
                                      }
                                      PositionSensor {
                                        name "head_pitch_sensor"
                                      }
                                    ]
                                    endPoint Solid {
                                      rotation 0 0.9999999976880001 6.7999999842784e-05 0
                                      children [
                                        Shape {
                                          appearance DEF head_pitch_material PBRAppearance {
                                            baseColor 0.15 0.15 0.15
                                            roughness 1
                                            metalness 0
                                          }
                                          geometry DEF head_pitch Mesh {
                                            url [
                                              "../meshes/head_pitch.STL"
                                            ]
                                          }
                                          castShadows FALSE
                                        }
                                      ]
                                      name "head_pitch"
                                      boundingObject Sphere {
                                        radius 0.07
                                      }
                                      physics Physics {
                                        density -1
                                        mass 0.315067
                                        centerOfMass [
                                          0.017994 0.000157 -0.010788
                                        ]
                                        inertiaMatrix [
                                          0.001004716 0.001052722 0.001141549
                                          -8.23898e-07 0.0002098761 2.28002e-06
                                        ]
                                      }
                                    }
                                  }
                                ]
                                name "head_roll"
                                physics Physics {
                                  density -1
                                  mass 0.018957
                                  centerOfMass [
                                    -0.00054 0.002997 -0.001947
                                  ]
                                  inertiaMatrix [
                                    3.07261e-06 5.660771e-06 3.718784e-06
                                    4.102927e-08 1.783123e-08 -1.517082e-08
                                  ]
                                }
                              }
                            }
                          ]
                          name "head_yaw"
                          physics Physics {
                            density -1
                            mass 0.168425
                            centerOfMass [
                              0.000255 -1.4e-05 0.057174
                            ]
                            inertiaMatrix [
                              0.000120637 0.0001324099 7.432741e-05
                              -5.932295e-09 -1.709793e-05 -4.692674e-08
                            ]
                          }
                        }
                      }
                    ]
                    name "waist_roll"
                    physics Physics {
                      density -1
                      mass 7.343926
                      centerOfMass [
                        -0.009828 -1.3e-05 0.160653
                      ]
                      inertiaMatrix [
                        0.03052609 0.02175674 0.01367875
                        -7.044068e-07 8.780922e-05 2.925281e-07
                      ]
                    }
                  }
                }
              ]
              name "waist_pitch"
              physics Physics {
                density -1
                mass 4.40328
                centerOfMass [
                  0.002292 -0.002294 0.042538
                ]
                inertiaMatrix [
                  0.004873232 0.004869337 0.003556898
                  -1.33065e-06 -4.026605e-05 -5.324685e-05
                ]
              }
            }
          }
        ]
        name "waist_yaw"
        boundingObject Pose {
          translation 0 0 -0.06
          rotation 1 0 0 1.57
          children [
            Cylinder {
              height 0.29
              radius 0.05
            }
          ]
        }
        physics Physics {
          density -1
          mass 0.37886
          centerOfMass [
            -0.010388 -0.001696 0.022471
          ]
          inertiaMatrix [
            0.0001969197 0.0003549922 0.0003836759
            2.123824e-08 2.56981e-05 2.241578e-10
          ]
        }
      }
    }
  ]
  name "SonnyV41"
  boundingObject Pose {
    translation 0 0 0.3
    children [
      Cylinder {
        height 0.2
        radius 0.1
      }
    ]
  }
  physics Physics {
    density -1
    mass 6.45117
    centerOfMass [
      -0.050889 0.000109 -0.045579
    ]
    inertiaMatrix [
      0.01492783 0.006409265 0.01279956
      1.726078e-05 -7.021831e-05 -3.163851e-06
    ]
  }
  controller "webots_interface"
  supervisor TRUE
}
